Workbook

Sheet Instructions
A1: Please complete Metadata_survey effort and Data return sheet, ensuring all fields are completed.
A2: *Only one data sheet should be filled in. The Data Return - Relocation (only) worksheet is for relocation projects.
A4: The below information is provided as a guide for the definition and requirements for each field for the Return Template.
A6: Column heading | B6: Values | C6: Description | D6: Notes
A7: AUTHORISATION_HOLDER | C7: Name on the Authorisations.
A8: NIL_RETURN | B8: Y or N | C8: This field indicates if fauna were taken or disturbed whilst completing work under the Authorisation. If fauna were taken or disturbed, this field will be ‘N.’ Entering ‘Y’ means it is a nil return.
A9: LOCATION | C9: This is the general locality name (e.g. shire or property name) for where the fauna survey was conducted.
A10: SITE | C10: This field allows for additional locality information, such as specific trap numbers or site locations.
A11: DATUM | B11: AGD66 AGD84 GDA94 or WGS84 | C11: This is the coordinate system from which spatial data is derived. It can only be one of the mentioned datum codes. | D11: Drop down list (highlighted yellow)
A12: LATITUDE | B12: E.g.: -33.5678 | C12: Latitude values must be provided as decimal degrees and must reference the site location and not the general locality. This number should be a negative value. | D12: Please note that this field may be left empty if a projected spatial value is provided.
A13: LONGITUDE | B13: E.g.: 115.3456 | C13: Longitude values must be provided as decimal degrees and must reference the site location and not the general locality. | D13: Please note that this field may be left empty if a projected spatial value is provided.
A14: ZONE | B14: 49 50 51 or 52 | C14: This is the projected map zone or UTM zone. | D14: Please note that this field may be left empty if a geographical spatial value is provided. Drop down list (highlighted yellow)
A15: EASTING | B15: E.g.:123456 | C15: The easting value will always have 6 digits and must reference the site location and not the general locality. | D15: Please note that this field may be left empty if a geographical spatial value is provided.
A16: NORTHING | B16: E.g.: 1234567 | C16: The northing value will always have 7 digits and must reference the site location and not the general locality. | D16: Please note that this field may be left empty if a geographical spatial value is provided.
A17: ACCURACY | B17: 1 2 3 4 5 6 | C17: 1 – within 100m of the site 2 – within 3km of the site 3 – within 10km of the site 4 – within 25km of the site 5 – within an area greater than 25km of the site 6 – Indefinable within Australia | D17: Drop down list (highlighted yellow) This is the level of accuracy of the spatial coordinates.
A18: TAKE/DISTURB_DATE | B18: DD/MM/YYYY | C18: This is the date of capture/take or observation/disturb of the fauna species being reported.
A19: SCIENTIFIC_NAME | C19: The scientific name for the species. | D19: Drop down list (highlighted yellow)
A20: COMMON_NAME | C20: The recognised common name for the species. | D20: Cell should autopopulate once species name is entered. Drop down list (highlighted yellow)
A21: NAME_ID | C21: This is the unique numeric identifier assigned to each taxon. | D21: Cell should autopopulate once species name is entered. Drop down list (highlighted yellow)
A22: WA STATUS | B22: CR EN VU P1 P2 P3 P4 CD MI | C22: Species conservation status in WA: CR - Critically Endangered EN - Endangered VU - Vulnerable P1 - Priority 1: poorly known species P2 - Priority 2: poorly known species P3 - Priority 3: poorly known species P4 - Priority 4: rare, near threatened and other species in need of monitoring S - Specially protected IA - International agreement EX - Extinct | D22: Cell should autopopulate once species name is entered. Drop down list (highlighted yellow)
A23: COUNT | C23: This column should indicate the number of individuals of each species observed at each site on each day of monitoring. You should only count each animal once per survey e.g. New animals and Recaptures for each survey.
A24: IDENTIFIER | C24: This column should have the full name of the person or organisation that has identified the species.
A25: CERTAINTY | B25: 1 2 3 4 | C25: 1 Not sure (Identified to family level or lower) 2 Moderately certain (Identified to genus level) 3 Certain (Identified to species level) 4 WAM Vouchered | D25: Drop down list (highlighted yellow)
A26: METHOD | B26: See data return sheet | C26: Activitye (trap type, handling method, technique to be undertaken) | D26: Drop down list (highlighted yellow)
A27: FATE | B27: See data return sheet | C27: Health status of the animal | D27: Drop down list (highlighted yellow)
A28: SAMPLES | B28: See data return sheet | C28: Biological samples collected. | D28: Drop down list (highlighted yellow)
A29: MARKING (Y/N) | B29: See data return sheet | C29: Confirmination of whether marking was undertaken. | D29: Drop down list (highlighted yellow)
A30: MARKING_METHOD | B30: See data return sheet | C30: Method used to permanently or temporarily mark an animal. | D30: Drop down list (highlighted yellow)
A31: TAG_ID | C31: Provide the unique identifer (e.g. ear tag or microchip number) associated with the corresponding method chosen in "Marking Method".
A32: MARKING_METHOD_2 | B32: See data return sheet | C32: Additonal marking method to permanently or temporarily mark an animal. | D32: Drop down list (highlighted yellow)
A33: TAG_ID_2 | C33: Provide the unique identifer (e.g. ear tag or microchip number) associated with the corresponding method chosen in "Marking Method 2".
A34: TRANSMITTER | B34: See data return sheet | C34: Type of tranmitter attached. | D34: Drop down list (highlighted yellow)
A35: VOUCHER_REF | C35: The voucher reference number is a unique reference that the licensee has associated with the species caught. This can include ear tag or micro-chip numbers.
A36: ADVERSE EVENT | B36: See data return sheet | C36: Notification of injury, death or unplanned euthanasia. | D36: Drop down list (highlighted yellow)
A37: CAPTURE STATUS | B37: See data return sheet | C37: Type of capture (new/recapture). | D37: Drop down list (highlighted yellow)
A38: COMMENTS (OTHER) | C38: Enter additonal information where 'other' was selected in any drop down list.

Sheet Metadata_Survey Effort
A1: AUTHORISATION_HOLDER | B1: AFFILIATION_COMPANY | C1: AUTHORISATION_NUMBER | D1: NIL_RETURN (Y/N)
A5: LOCATION | B5: SITE | C5: Survey session start date | D5: Survey session end date | E5: Method | F5: Number of traps at site | G5: Number of nights | H5: Comments
A6: Example:
A7: Busselton | B7: Ted Street Reserve | C7: 43836 | D7: 43957 | E7: small cage trap, treadle | F7: 20 | G7: 4
A8: Busselton | B8: Ted Street Reserve | C8: 43836 | D8: 43957 | E8: Aluminium box trap (e.g. Elliott) | F8: 40 | G8: 4
A9: Busselton | B9: Ted Street Reserve | C9: 43836 | D9: 43957 | E9: Dry pitfall trap | F9: 50 | G9: 3 | H9: Closed due to increased ant activity
A10: Busselton | B10: Ted Street Reserve | C10: 43836 | D10: 43957 | E10: Funnel trap | F10: 20 | G10: 4

Sheet Data Return
A1: LOCATION | B1: SITE | C1: DATUM | D1: LATITUDE | E1: LONGITUDE | F1: ZONE | G1: EASTING | H1: NORTHING | I1: ACCURACY | J1: TAKE/DISTURB_DATE | K1: SCIENTIFIC_NAME | L1: COMMON_NAME | M1: NAME_ID | N1: WA_STATUS | O1: COUNT | P1: IDENTIFIER | Q1: CERTAINTY | R1: METHOD | S1: FATE | T1: SAMPLES_1 | U1: SAMPLES_2 | V1: SAMPLES_3 | W1: MARKING | X1: MARKING_METHOD | Y1: TAG_ID | Z1: MARKING_METHOD_2 | AA1: TAG_ID_2 | AB1: TRANSMITTER | AC1: VOUCHER_REF | AD1: ADVERSE_EVENT | AE1: CAPTURE_STATUS | AF1: COMMENTS (OTHER)
L2: =VLOOKUP(K2,Species!$A$2:$D$2230,2,FALSE) -> #N/A | M2: =VLOOKUP(K2,Species!$A$2:$D$2230,3,FALSE) -> #N/A | N2: =VLOOKUP(K2,Species!$A$2:$D$2230,4,FALSE) -> #N/A
L3: =VLOOKUP(K3,Species!$A$2:$D$2230,2,FALSE) -> #N/A | M3: =VLOOKUP(K3,Species!$A$2:$D$2230,3,FALSE) -> #N/A | N3: =VLOOKUP(K3,Species!$A$2:$D$2230,4,FALSE) -> #N/A
L4: =VLOOKUP(K4,Species!$A$2:$D$2230,2,FALSE) -> #N/A | M4: =VLOOKUP(K4,Species!$A$2:$D$2230,3,FALSE) -> #N/A | N4: =VLOOKUP(K4,Species!$A$2:$D$2230,4,FALSE) -> #N/A
L5: =VLOOKUP(K5,Species!$A$2:$D$2230,2,FALSE) -> #N/A | M5: =VLOOKUP(K5,Species!$A$2:$D$2230,3,FALSE) -> #N/A | N5: =VLOOKUP(K5,Species!$A$2:$D$2230,4,FALSE) -> #N/A
L6: =VLOOKUP(K6,Species!$A$2:$D$2230,2,FALSE) -> #N/A | M6: =VLOOKUP(K6,Species!$A$2:$D$2230,3,FALSE) -> #N/A | N6: =VLOOKUP(K6,Species!$A$2:$D$2230,4,FALSE) -> #N/A
L7: =VLOOKUP(K7,Species!$A$2:$D$2230,2,FALSE) -> #N/A | M7: =VLOOKUP(K7,Species!$A$2:$D$2230,3,FALSE) -> #N/A | N7: =VLOOKUP(K7,Species!$A$2:$D$2230,4,FALSE) -> #N/A
L8: =VLOOKUP(K8,Species!$A$2:$D$2230,2,FALSE) -> #N/A | M8: =VLOOKUP(K8,Species!$A$2:$D$2230,3,FALSE) -> #N/A | N8: =VLOOKUP(K8,Species!$A$2:$D$2230,4,FALSE) -> #N/A
L9: =VLOOKUP(K9,Species!$A$2:$D$2230,2,FALSE) -> #N/A | M9: =VLOOKUP(K9,Species!$A$2:$D$2230,3,FALSE) -> #N/A | N9: =VLOOKUP(K9,Species!$A$2:$D$2230,4,FALSE) -> #N/A
L10: =VLOOKUP(K10,Species!$A$2:$D$2230,2,FALSE) -> #N/A | M10: =VLOOKUP(K10,Species!$A$2:$D$2230,3,FALSE) -> #N/A | N10: =VLOOKUP(K10,Species!$A$2:$D$2230,4,FALSE) -> #N/A
L11: =VLOOKUP(K11,Species!$A$2:$D$2230,2,FALSE) -> #N/A | M11: =VLOOKUP(K11,Species!$A$2:$D$2230,3,FALSE) -> #N/A | N11: =VLOOKUP(K11,Species!$A$2:$D$2230,4,FALSE) -> #N/A
L12: =VLOOKUP(K12,Species!$A$2:$D$2230,2,FALSE) -> #N/A | M12: =VLOOKUP(K12,Species!$A$2:$D$2230,3,FALSE) -> #N/A | N12: =VLOOKUP(K12,Species!$A$2:$D$2230,4,FALSE) -> #N/A
L13: =VLOOKUP(K13,Species!$A$2:$D$2230,2,FALSE) -> #N/A | M13: =VLOOKUP(K13,Species!$A$2:$D$2230,3,FALSE) -> #N/A | N13: =VLOOKUP(K13,Species!$A$2:$D$2230,4,FALSE) -> #N/A
... L200: =VLOOKUP(K200,Species!$A$2:$D$2230,2,FALSE) -> #N/A | M200: =VLOOKUP(K200,Species!$A$2:$D$2230,3,FALSE) -> #N/A | N200: =VLOOKUP(K200,Species!$A$2:$D$2230,4,FALSE) -> #N/A

Sheet Data Return - Relocation (ONLY)
A1: LOCATION | B1: CAPTURE_SITE | C1: DATUM | D1: LATITUDE | E1: LONGITUDE | F1: ZONE | G1: EASTING | H1: NORTHING | I1: ACCURACY | J1: CAPTURE_DATE | K1: RELEASE_SITE | L1: DATUM | M1: LATITUDE | N1: LONGITUDE | O1: ZONE | P1: EASTING | Q1: NORTHING | R1: ACCURACY | S1: RELEASE_DATE | T1: SCIENTIFIC_NAME | U1: COMMON_NAME | V1: NAME_ID | W1: WA_STATUS | X1: COUNT | Y1: IDENTIFIER | Z1: CERTAINTY | AA1: METHOD | AB1: FATE | AC1: SAMPLES_1 | AD1: SAMPLES_2 | AE1: SAMPLES_3 | AF1: MARKING | AG1: MARKING_METHOD | AH1: TAG ID | AI1: MARKING_METHOD_2 | AJ1: TAG ID 2 | AK1: TRANSMITTER | AL1: VOUCHER_REF | AM1: ADVERSE_EVENT | AN1: CAPTURE_STATUS | AO1: COMMENTS (OTHER)
U2: =VLOOKUP(T2,Species!$A$2:$D$2230,2,FALSE) -> #N/A | V2: =VLOOKUP(T2,Species!$A$2:$D$2230,3,FALSE) -> #N/A | W2: =VLOOKUP(T2,Species!$A$2:$D$2230,4,FALSE) -> #N/A
U3: =VLOOKUP(T3,Species!$A$2:$D$2230,2,FALSE) -> #N/A | V3: =VLOOKUP(T3,Species!$A$2:$D$2230,3,FALSE) -> #N/A | W3: =VLOOKUP(T3,Species!$A$2:$D$2230,4,FALSE) -> #N/A
U4: =VLOOKUP(T4,Species!$A$2:$D$2230,2,FALSE) -> #N/A | V4: =VLOOKUP(T4,Species!$A$2:$D$2230,3,FALSE) -> #N/A | W4: =VLOOKUP(T4,Species!$A$2:$D$2230,4,FALSE) -> #N/A
U5: =VLOOKUP(T5,Species!$A$2:$D$2230,2,FALSE) -> #N/A | V5: =VLOOKUP(T5,Species!$A$2:$D$2230,3,FALSE) -> #N/A | W5: =VLOOKUP(T5,Species!$A$2:$D$2230,4,FALSE) -> #N/A
U6: =VLOOKUP(T6,Species!$A$2:$D$2230,2,FALSE) -> #N/A | V6: =VLOOKUP(T6,Species!$A$2:$D$2230,3,FALSE) -> #N/A | W6: =VLOOKUP(T6,Species!$A$2:$D$2230,4,FALSE) -> #N/A
U7: =VLOOKUP(T7,Species!$A$2:$D$2230,2,FALSE) -> #N/A | V7: =VLOOKUP(T7,Species!$A$2:$D$2230,3,FALSE) -> #N/A | W7: =VLOOKUP(T7,Species!$A$2:$D$2230,4,FALSE) -> #N/A
U8: =VLOOKUP(T8,Species!$A$2:$D$2230,2,FALSE) -> #N/A | V8: =VLOOKUP(T8,Species!$A$2:$D$2230,3,FALSE) -> #N/A | W8: =VLOOKUP(T8,Species!$A$2:$D$2230,4,FALSE) -> #N/A
U9: =VLOOKUP(T9,Species!$A$2:$D$2230,2,FALSE) -> #N/A | V9: =VLOOKUP(T9,Species!$A$2:$D$2230,3,FALSE) -> #N/A | W9: =VLOOKUP(T9,Species!$A$2:$D$2230,4,FALSE) -> #N/A
U10: =VLOOKUP(T10,Species!$A$2:$D$2230,2,FALSE) -> #N/A | V10: =VLOOKUP(T10,Species!$A$2:$D$2230,3,FALSE) -> #N/A | W10: =VLOOKUP(T10,Species!$A$2:$D$2230,4,FALSE) -> #N/A
U11: =VLOOKUP(T11,Species!$A$2:$D$2230,2,FALSE) -> #N/A | V11: =VLOOKUP(T11,Species!$A$2:$D$2230,3,FALSE) -> #N/A | W11: =VLOOKUP(T11,Species!$A$2:$D$2230,4,FALSE) -> #N/A
U12: =VLOOKUP(T12,Species!$A$2:$D$2230,2,FALSE) -> #N/A | V12: =VLOOKUP(T12,Species!$A$2:$D$2230,3,FALSE) -> #N/A | W12: =VLOOKUP(T12,Species!$A$2:$D$2230,4,FALSE) -> #N/A
U13: =VLOOKUP(T13,Species!$A$2:$D$2230,2,FALSE) -> #N/A | V13: =VLOOKUP(T13,Species!$A$2:$D$2230,3,FALSE) -> #N/A | W13: =VLOOKUP(T13,Species!$A$2:$D$2230,4,FALSE) -> #N/A
... U200: =VLOOKUP(T200,Species!$A$2:$D$2230,2,FALSE) -> #N/A | V200: =VLOOKUP(T200,Species!$A$2:$D$2230,3,FALSE) -> #N/A | W200: =VLOOKUP(T200,Species!$A$2:$D$2230,4,FALSE) -> #N/A

Sheet Look-up Values
A1: METHOD | B1: FATE | C1: SAMPLES | D1: MARKING | E1: MARKING_METHOD | F1: MARKING_METHOD_2 | G1: TRANSMITTER | H1: ADVERSE_EVENT | I1: CAPTURE_STATUS | J1: DATUM | K1: ZONE | L1: ACCURACY | N1: CERTAINTY
A2: Aluminium box trap (e.g. Elliott) | B2: N/A (Observational only) | C2: Nil | D2: Not marked | E2: Nil | F2: Nil | G2: Nil | H2: Nil | I2: N/A | J2: AGD66 | K2: 49 | L2: 1 | M2: 1 – within 100m of the site | N2: 1 | O2: 1 Not sure (Identified to family level or lower)
A3: Small cage trap, treadle | B3: Released at capture site | C3: Tissue | D3: Marked | E3: Ear tag | F3: Ear tag | G3: Collar | H3: Unplanned euthanasia | I3: New capture | J3: AGD84 | K3: 50 | L3: 2 | M3: 2 – within 3km of the site | N3: 2 | O3: 2 Moderately certain (Identified to genus level)
A4: Medium cage trap, treadle | B4: Released at capture site (minor injury) | C4: Scale clip | E4: Wing band | F4: Wing band | G4: Harness | H4: Unplanned death | I4: Recapture, previous session | J4: GDA94 | K4: 51 | L4: 3 | M4: 3 – within 10km of the site | N4: 3 | O4: 3 Certain (Identified to species level)
A5: Large cage trap, treadle | B5: Released adjacent to capture site | C5: Blood | E5: Leg band | F5: Leg band | G5: Tail mount | H5: Injury | I5: Recapture, same session | J5: WGS84 | K5: 52 | L5: 4 | M5: 4 – within 25km of the site | N5: 4 | O5: 4 WAM Vouchered
A6: Thomas trap | B6: Released adjacent to capture site (minor injury) | C6: Swab | E6: PIT implant/microchip | F6: PIT implant/microchip | G6: Glued/adhered transmitter | H6: Abandoned young or eggs | I6: Other | L6: 5 | M6: 5 – within an area greater than 25km of the site
A7: Bromilow Trap | B7: Released at approved non-adjacent site | C7: Hair/feather | E7: Scale clip | F7: Scale clip | G7: Implanted transmitter | H7: Other | L7: 6 | M7: 6 – Indefinable within Australia
A8: Wet pitfall trap | B8: Released at approved non-adjacent site (minor injury) | C8: Other | E8: Ear notch | F8: Ear notch | G8: Other
A9: Dry pitfall trap | B9: Taken for captive breeding | E9: Temporary marking (e.g. marker pen, dye, streamers, hair removal) | F9: Temporary marking (e.g. marker pen, dye, streamers, hair removal)
A10: Funnel trap | B10: Taken for captivity (e.g. display) | E10: Flipper tagging | F10: Flipper tagging
A11: Harp trap | B11: Taken for long-term use (greater than 72 hours), with intent of release | E11: Other | F11: Other
A12: Fyke net | B12: Taken for permanent use (scientific research), no release
A13: Seine net | B13: Taken live for identification and released within 24 hours
A14: Cathedral or opera trap | B14: Taken into care
A15: Hand net | B15: Deceased in trap
A16: Mist net | B16: Died during handling procedures
A17: Cannon net | B17: Died during transport
A18: Noose and tong | B18: Euthanasied (pest)
A19: Hand capture | B19: Euthanised for welfare reasons
A20: Darting | B20: Mother and PY intervention, successful
A21: Corral into containment | B21: Mother and PY intervention, failed
A22: Haul, srapes and/or bailers (e.g. stygofauna) | B22: Vouchered
A23: Displacement | B23: Other
A24: Hair trap
A25: Lured/baited (consumable) remote camera
A26: Lured/baited (non-consumable) remote camera
A27: Spotlighting
A28: Drone captured photos/video
A29: Hollow/nest box monitoring (e.g. camera, knock, tap)
A30: Direct observation (e.g. bird survey, mound monitoring)
A31: Indirect observation (e.g sand plot, scat plot, tracks)
A32: Acoustic recorder (e.g. placed inside caves (bats), suitable habitat (night parrot)
A33: Other

Sheet Species
A1: SPECIES_NAME | B1: VERNACULAR | C1: NAME_ID | D1: CONSV_CODE
A2: Abebaioscia troglodytes | B2: Pannikin Plain Cave Isopod | C2: 33930 | D2: VU
A3: Acanthagenys rufogularis | B3: Spiny-cheeked Honeyeater | C3: 24559
A4: Acanthiza apicalis | B4: Broad-tailed Thornbill | C4: 24260
A5: Acanthiza apicalis apicalis | B5: Broad-tailed Thornbill | C5: 47353
A6: Acanthiza chrysorrhoa | B6: Yellow-rumped Thornbill | C6: 24261
A7: Acanthiza chrysorrhoa chrysorrhoa | B7: Yellow-rumped Thornbill | C7: 47373
A8: Acanthiza inornata | B8: Western Thornbill | C8: 24262
A9: Acanthiza iredalei | B9: Samphire Thornbill | C9: 25527
A10: Acanthiza iredalei iredalei | B10: Samphire Thornbill | C10: 24263
A11: Acanthiza robustirostris | B11: Slaty-backed Thornbill | C11: 24264
A12: Acanthiza uropygialis | B12: Chestnut-rumped Thornbill | C12: 24265
A13: Acanthophis antarcticus | B13: Southern Death Adder | C13: 25242 | D13: P3
A14: Acanthophis praelongus | B14: Northern Death Adder | C14: 25330
A15: Acanthophis pyrrhus | B15: Desert Death Adder | C15: 25243
A16: Acanthophis wellsi | B16: Pilbara Death Adder | C16: 25332
A17: Acanthorhynchus superciliosus | B17: Western Spinebill | C17: 24560
A18: Accipiter cirrocephalus | B18: Collared Sparrowhawk | C18: 25535
A19: Accipiter cirrocephalus cirrocephalus | B19: Collared Sparrowhawk | C19: 24281
A20: Accipiter fasciatus | B20: Brown Goshawk | C20: 25536
A21: Accipiter fasciatus didimus | B21: Brown Goshawk | C21: 24283
A22: Accipiter fasciatus fasciatus | B22: Brown Goshawk | C22: 24282
A23: Accipiter novaehollandiae | B23: Grey Goshawk | C23: 25537
A24: Accipiter novaehollandiae novaehollandiae | B24: Grey Goshawk | C24: 24284
A25: Acercella poorginup | B25: Poorginup Swamp Watermite | C25: 33901 | D25: P2
A26: Acizzia mccarthyi | B26: McCarthy's plant-louse | C26: 44615 | D26: VU
A27: Acizzia veski | B27: Vesk's plant-louse | C27: 41374 | D27: VU
A28: Acridotheres tristis | B28: Common Myna | C28: 25751
A29: Acridotheres tristis [tristis] | B29: Common Myna | C29: 24823
A30: Acritoscincus trilineatus | B30: Western Three-lined Skink | C30: 42368
A31: Acrocephalus australis | B31: Australian Reed Warbler | C31: 25755
A32: Acrocephalus australis gouldi | B32: Australian Reed Warbler | C32: 24831
A33: Acrocephalus orientalis | B33: Oriental Reed Warbler | C33: 24832 | D33: IA
A34: Acrochordus granulatus | B34: Little Wart-snake | C34: 25323
A35: Actitis hypoleucos | B35: Common Sandpiper | C35: 41323 | D35: IA
A36: Aegotheles cristatus | B36: Australian Owlet-nightjar | C36: 25544
A37: Aegotheles cristatus cristatus | B37: Australian Owlet-nightjar | C37: 24301
A38: Aegotheles cristatus leucogaster | B38: Australian Owlet-nightjar | C38: 24300
A39: Aganippe castellum | B39: Tree-stem Trapdoor Spider | C39: 33902 | D39: P4
A40: Aipysurus apraefrontalis | B40: Short-nosed Seasnake | C40: 25350 | D40: CR
...
